Workbook
Name Slicer_Category: #N/A
Name Slicer_Order_Year: #N/A
Name Slicer_Region: #N/A
Name Slicer_Segment: #N/A

Sheet Orders
A1: Customer_ID | B1: Product_ID | C1: Order_ID | D1: Order_Date | E1: Order_Year | F1: Order_Month | G1: Ship_Date | H1: Customer_Name | I1: Segment | J1: Region | K1: Category | L1: Sub_Category | M1: Sales | N1: Profit | O1: Discount
A2: =_xlfn.XLOOKUP(H2, 'Customers'!B:B, 'Customers'!A:A) -> CUST_1 | B2: =_xlfn.XLOOKUP(L2, Products!C:C, Products!A:A) -> PROD_1 | C2: 1 | D2: 2023-09-02 | E2: =YEAR(Orders[[#This Row],[Order_Date]]) -> 2023 | F2: =MONTH(Orders[[#This Row],[Order_Date]]) -> 9 | G2: 2023-09-07 | H2: Customer_989 | I2: Consumer | J2: North | K2: Fashion | L2: Accessories | M2: 7497.79 | N2: 1775.3 | O2: 0.1
A3: =_xlfn.XLOOKUP(H3, 'Customers'!B:B, 'Customers'!A:A) -> CUST_2 | B3: =_xlfn.XLOOKUP(L3, Products!C:C, Products!A:A) -> PROD_2 | C3: 2 | D3: 2023-04-17 | E3: =YEAR(Orders[[#This Row],[Order_Date]]) -> 2023 | F3: =MONTH(Orders[[#This Row],[Order_Date]]) -> 4 | G3: 2023-04-19 | H3: Customer_605 | I3: Corporate | J3: South | K3: Fashion | L3: Clothing | M3: 1385.9 | N3: 333.77 | O3: 0.24
A4: =_xlfn.XLOOKUP(H4, 'Customers'!B:B, 'Customers'!A:A) -> CUST_3 | B4: =_xlfn.XLOOKUP(L4, Products!C:C, Products!A:A) -> PROD_3 | C4: 3 | D4: 2023-01-05 | E4: =YEAR(Orders[[#This Row],[Order_Date]]) -> 2023 | F4: =MONTH(Orders[[#This Row],[Order_Date]]) -> 1 | G4: 2023-01-10 | H4: Customer_650 | I4: Corporate | J4: North | K4: Electronics | L4: Laptop | M4: 1647.03 | N4: 146.19 | O4: 0.12
A5: =_xlfn.XLOOKUP(H5, 'Customers'!B:B, 'Customers'!A:A) -> CUST_4 | B5: =_xlfn.XLOOKUP(L5, Products!C:C, Products!A:A) -> PROD_4 | C5: 4 | D5: 2023-05-02 | E5: =YEAR(Orders[[#This Row],[Order_Date]]) -> 2023 | F5: =MONTH(Orders[[#This Row],[Order_Date]]) -> 5 | G5: 2023-05-06 | H5: Customer_483 | I5: Home Office | J5: East | K5: Furniture | L5: Storage | M5: 9511.07 | N5: 2539.61 | O5: 0.19
A6: =_xlfn.XLOOKUP(H6, 'Customers'!B:B, 'Customers'!A:A) -> CUST_5 | B6: =_xlfn.XLOOKUP(L6, Products!C:C, Products!A:A) -> PROD_5 | C6: 5 | D6: 2023-10-05 | E6: =YEAR(Orders[[#This Row],[Order_Date]]) -> 2023 | F6: =MONTH(Orders[[#This Row],[Order_Date]]) -> 10 | G6: 2023-10-10 | H6: Customer_634 | I6: Consumer | J6: North | K6: Furniture | L6: Chair | M6: 4921.84 | N6: 740.11 | O6: 0.28
A7: =_xlfn.XLOOKUP(H7, 'Customers'!B:B, 'Customers'!A:A) -> CUST_6 | B7: =_xlfn.XLOOKUP(L7, Products!C:C, Products!A:A) -> PROD_2 | C7: 6 | D7: 2023-03-20 | E7: =YEAR(Orders[[#This Row],[Order_Date]]) -> 2023 | F7: =MONTH(Orders[[#This Row],[Order_Date]]) -> 3 | G7: 2023-03-22 | H7: Customer_478 | I7: Consumer | J7: South | K7: Fashion | L7: Clothing | M7: 399.85 | N7: -6.89 | O7: 0.1
A8: =_xlfn.XLOOKUP(H8, 'Customers'!B:B, 'Customers'!A:A) -> CUST_7 | B8: =_xlfn.XLOOKUP(L8, Products!C:C, Products!A:A) -> PROD_1 | C8: 7 | D8: 2023-12-21 | E8: =YEAR(Orders[[#This Row],[Order_Date]]) -> 2023 | F8: =MONTH(Orders[[#This Row],[Order_Date]]) -> 12 | G8: 2023-12-24 | H8: Customer_800 | I8: Corporate | J8: East | K8: Electronics | L8: Accessories | M8: 7074.73 | N8: 1797.36 | O8: 0.25
A9: =_xlfn.XLOOKUP(H9, 'Customers'!B:B, 'Customers'!A:A) -> CUST_8 | B9: =_xlfn.XLOOKUP(L9, Products!C:C, Products!A:A) -> PROD_1 | C9: 8 | D9: 2023-02-13 | E9: =YEAR(Orders[[#This Row],[Order_Date]]) -> 2023 | F9: =MONTH(Orders[[#This Row],[Order_Date]]) -> 2 | G9: 2023-02-18 | H9: Customer_397 | I9: Consumer | J9: North | K9: Fashion | L9: Accessories | M9: 5250.91 | N9: -489.08 | O9: 0.2
A10: =_xlfn.XLOOKUP(H10, 'Customers'!B:B, 'Customers'!A:A) -> CUST_9 | B10: =_xlfn.XLOOKUP(L10, Products!C:C, Products!A:A) -> PROD_6 | C10: 9 | D10: 2022-09-23 | E10: =YEAR(Orders[[#This Row],[Order_Date]]) -> 2022 | F10: =MONTH(Orders[[#This Row],[Order_Date]]) -> 9 | G10: 2022-09-24 | H10: Customer_530 | I10: Corporate | J10: East | K10: Furniture | L10: Table | M10: 9029.77 | N10: -185.11 | O10: 0.21
A11: =_xlfn.XLOOKUP(H11, 'Customers'!B:B, 'Customers'!A:A) -> CUST_10 | B11: =_xlfn.XLOOKUP(L11, Products!C:C, Products!A:A) -> PROD_3 | C11: 10 | D11: 2022-02-07 | E11: =YEAR(Orders[[#This Row],[Order_Date]]) -> 2022 | F11: =MONTH(Orders[[#This Row],[Order_Date]]) -> 2 | G11: 2022-02-10 | H11: Customer_705 | I11: Consumer | J11: North | K11: Electronics | L11: Laptop | M11: 1159.02 | N11: 183.08 | O11: 0.29
A12: =_xlfn.XLOOKUP(H12, 'Customers'!B:B, 'Customers'!A:A) -> CUST_11 | B12: =_xlfn.XLOOKUP(L12, Products!C:C, Products!A:A) -> PROD_5 | C12: 11 | D12: 2023-06-19 | E12: =YEAR(Orders[[#This Row],[Order_Date]]) -> 2023 | F12: =MONTH(Orders[[#This Row],[Order_Date]]) -> 6 | G12: 2023-06-24 | H12: Customer_690 | I12: Home Office | J12: South | K12: Furniture | L12: Chair | M12: 4423.62 | N12: -66.36 | O12: 0.3
A13: =_xlfn.XLOOKUP(H13, 'Customers'!B:B, 'Customers'!A:A) -> CUST_12 | B13: =_xlfn.XLOOKUP(L13, Products!C:C, Products!A:A) -> PROD_3 | C13: 12 | D13: 2022-09-12 | E13: =YEAR(Orders[[#This Row],[Order_Date]]) -> 2022 | F13: =MONTH(Orders[[#This Row],[Order_Date]]) -> 9 | G13: 2022-09-13 | H13: Customer_748 | I13: Home Office | J13: North | K13: Electronics | L13: Laptop | M13: 7760.97 | N13: 2324.87 | O13: 0.28
... A20001: =_xlfn.XLOOKUP(H20001, 'Customers'!B:B, 'Customers'!A:A) -> CUST_903 | B20001: =_xlfn.XLOOKUP(L20001, Products!C:C, Products!A:A) -> PROD_1 | C20001: 20000 | D20001: 2022-05-30 | E20001: =YEAR(Orders[[#This Row],[Order_Date]]) -> 2022 | F20001: =MONTH(Orders[[#This Row],[Order_Date]]) -> 5 | G20001: 2022-06-01 | H20001: Customer_915 | I20001: Corporate | J20001: North | K20001: Electronics | L20001: Accessories | M20001: 4496.71 | N20001: 506.66 | O20001: 0.08

Sheet Products
A1: Product_ID | B1: Category | C1: Sub_Category
A2: ="PROD_" & ROW()-1 -> PROD_1 | B2: Fashion | C2: Accessories
A3: ="PROD_" & ROW()-1 -> PROD_2 | B3: Fashion | C3: Clothing
A4: ="PROD_" & ROW()-1 -> PROD_3 | B4: Electronics | C4: Laptop
A5: ="PROD_" & ROW()-1 -> PROD_4 | B5: Furniture | C5: Storage
A6: ="PROD_" & ROW()-1 -> PROD_5 | B6: Furniture | C6: Chair
A7: ="PROD_" & ROW()-1 -> PROD_6 | B7: Furniture | C7: Table
A8: ="PROD_" & ROW()-1 -> PROD_7 | B8: Fashion | C8: Footwear
A9: ="PROD_" & ROW()-1 -> PROD_8 | B9: Electronics | C9: Mobile

Sheet Customers
A1: Customer_ID | B1: Customer_Name | C1: Segment | D1: Region
A2: ="CUST_" & ROW()-1 -> CUST_1 | B2: Customer_989 | C2: Consumer | D2: North
A3: ="CUST_" & ROW()-1 -> CUST_2 | B3: Customer_605 | C3: Corporate | D3: South
A4: ="CUST_" & ROW()-1 -> CUST_3 | B4: Customer_650 | C4: Corporate | D4: North
A5: ="CUST_" & ROW()-1 -> CUST_4 | B5: Customer_483 | C5: Home Office | D5: East
A6: ="CUST_" & ROW()-1 -> CUST_5 | B6: Customer_634 | C6: Consumer | D6: North
A7: ="CUST_" & ROW()-1 -> CUST_6 | B7: Customer_478 | C7: Consumer | D7: South
A8: ="CUST_" & ROW()-1 -> CUST_7 | B8: Customer_800 | C8: Corporate | D8: East
A9: ="CUST_" & ROW()-1 -> CUST_8 | B9: Customer_397 | C9: Consumer | D9: North
A10: ="CUST_" & ROW()-1 -> CUST_9 | B10: Customer_530 | C10: Corporate | D10: East
A11: ="CUST_" & ROW()-1 -> CUST_10 | B11: Customer_705 | C11: Consumer | D11: North
A12: ="CUST_" & ROW()-1 -> CUST_11 | B12: Customer_690 | C12: Home Office | D12: South
A13: ="CUST_" & ROW()-1 -> CUST_12 | B13: Customer_748 | C13: Home Office | D13: North
... A1001: ="CUST_" & ROW()-1 -> CUST_1000 | B1001: Customer_271 | C1001: Home Office | D1001: North

Sheet Data For DashBoard
B8: Total Sales | C8: Total Profit | D8: Total Orders | E8: Profit Margin %
B9: 1.0193328e+08 | C9: 10331395 | D9: 20000 | E9: 0.10135448
B15: Row Labels | C15: Sum of Sales
B16: 2022
B17: 1 | C17: 4158475.9
B18: 2 | C18: 3982263.2
B19: 3 | C19: 4272073.8
B20: 4 | C20: 4286140.8
B21: 5 | C21: 4437656.7
B22: 6 | C22: 4166499.4
B23: 7 | C23: 4061475.9
B24: 8 | C24: 4386551.5
B25: 9 | C25: 4219240.5
B26: 10 | C26: 4392500.3
B27: 11 | C27: 4413392.7
B28: 12 | C28: 4119086.7
B29: 2023
B30: 1 | C30: 4507125.8
B31: 2 | C31: 4053749.8
B32: 3 | C32: 4310493.2
B33: 4 | C33: 3983735.3
B34: 5 | C34: 4097966.3
B35: 6 | C35: 4226175.4
B36: 7 | C36: 4387773.1
B37: 8 | C37: 4470189.1
B38: 9 | C38: 4231082
B39: 10 | C39: 4240987.9
B40: 11 | C40: 3980654.1
B41: 12 | C41: 4417438.2
B42: Grand Total | C42: 1.0180273e+08
B46: Row Labels | C46: Sum of Sales
B47: Electronics | C47: 22310643
B48: Fashion | C48: 45700443
B49: Furniture | C49: 33922196
B50: Grand Total | C50: 1.0193328e+08
B63: Row Labels | C63: Sum of Sales
B64: Accessories | C64: 22642022
B65: Chair | C65: 11311834
B66: Clothing | C66: 11636798
B67: Footwear | C67: 11421624
...

Sheet DashBoard
F1: E-commerce Sales Performance Dashboard
C6: Total Sales | G6: Total Profit | K6: Total Orders | O6: Profit Margin %
C8: =GETPIVOTDATA("[Measures].[Total Sales]",'Data For DashBoard'!$B$8) -> 1.0193328e+08 | G8: =GETPIVOTDATA("[Measures].[Total Profit]",'Data For DashBoard'!$B$8) -> 10331395 | K8: =GETPIVOTDATA("[Measures].[Total Orders]",'Data For DashBoard'!$B$8) -> 20000 | O8: =GETPIVOTDATA("[Measures].[Profit Margin %]",'Data For DashBoard'!$B$8) -> 0.10135448
